[2024-04-04T09:56:52.923+0000] {taskinstance.py:1979} INFO - Dependencies all met for dep_context=non-requeueable deps ti=<TaskInstance: nhom7_scrapy_dag.crawl_job_task manual__2024-04-04T09:56:50.818287+00:00 [queued]>
[2024-04-04T09:56:52.939+0000] {taskinstance.py:1979} INFO - Dependencies all met for dep_context=requeueable deps ti=<TaskInstance: nhom7_scrapy_dag.crawl_job_task manual__2024-04-04T09:56:50.818287+00:00 [queued]>
[2024-04-04T09:56:52.940+0000] {taskinstance.py:2193} INFO - Starting attempt 1 of 1
[2024-04-04T09:56:52.964+0000] {taskinstance.py:2217} INFO - Executing <Task(BashOperator): crawl_job_task> on 2024-04-04 09:56:50.818287+00:00
[2024-04-04T09:56:52.972+0000] {standard_task_runner.py:60} INFO - Started process 328 to run task
[2024-04-04T09:56:52.974+0000] {standard_task_runner.py:87} INFO - Running: ['***', 'tasks', 'run', 'nhom7_scrapy_dag', 'crawl_job_task', 'manual__2024-04-04T09:56:50.818287+00:00', '--job-id', '5', '--raw', '--subdir', 'DAGS_FOLDER/nhom7_scarpy_dag.py', '--cfg-path', '/tmp/tmpwc92p1f6']
[2024-04-04T09:56:52.977+0000] {standard_task_runner.py:88} INFO - Job 5: Subtask crawl_job_task
[2024-04-04T09:56:53.027+0000] {task_command.py:423} INFO - Running <TaskInstance: nhom7_scrapy_dag.crawl_job_task manual__2024-04-04T09:56:50.818287+00:00 [running]> on host 278d2a481351
[2024-04-04T09:56:53.108+0000] {taskinstance.py:2513} INFO - Exporting env vars: AIRFLOW_CTX_DAG_EMAIL='hieurio12@gmail.com' AIRFLOW_CTX_DAG_OWNER='hieurio' AIRFLOW_CTX_DAG_ID='nhom7_scrapy_dag' AIRFLOW_CTX_TASK_ID='crawl_job_task' AIRFLOW_CTX_EXECUTION_DATE='2024-04-04T09:56:50.818287+00:00' AIRFLOW_CTX_TRY_NUMBER='1' AIRFLOW_CTX_DAG_RUN_ID='manual__2024-04-04T09:56:50.818287+00:00'
[2024-04-04T09:56:53.111+0000] {subprocess.py:63} INFO - Tmp dir root location: /tmp
[2024-04-04T09:56:53.112+0000] {subprocess.py:75} INFO - Running command: ['/usr/bin/bash', '-c', 'source activate venv && scrapy crawl careerlink_spider']
[2024-04-04T09:56:53.126+0000] {subprocess.py:86} INFO - Output:
[2024-04-04T09:56:53.132+0000] {subprocess.py:93} INFO - /usr/bin/bash: line 1: activate: No such file or directory
[2024-04-04T09:56:53.133+0000] {subprocess.py:97} INFO - Command exited with return code 1
[2024-04-04T09:56:53.148+0000] {taskinstance.py:2731} ERROR - Task failed with exception
Traceback (most recent call last):
  File "/home/airflow/.local/lib/python3.8/site-packages/airflow/models/taskinstance.py", line 444, in _execute_task
    result = _execute_callable(context=context, **execute_callable_kwargs)
  File "/home/airflow/.local/lib/python3.8/site-packages/airflow/models/taskinstance.py", line 414, in _execute_callable
    return execute_callable(context=context, **execute_callable_kwargs)
  File "/home/airflow/.local/lib/python3.8/site-packages/airflow/operators/bash.py", line 212, in execute
    raise AirflowException(
airflow.exceptions.AirflowException: Bash command failed. The command returned a non-zero exit code 1.
[2024-04-04T09:56:53.155+0000] {taskinstance.py:1149} INFO - Marking task as FAILED. dag_id=nhom7_scrapy_dag, task_id=crawl_job_task, execution_date=20240404T095650, start_date=20240404T095652, end_date=20240404T095653
[2024-04-04T09:56:53.188+0000] {warnings.py:109} WARNING - /home/***/.local/lib/python3.8/site-packages/***/utils/email.py:154: RemovedInAirflow3Warning: Fetching SMTP credentials from configuration variables will be deprecated in a future release. Please set credentials using a connection instead.
  send_mime_email(e_from=mail_from, e_to=recipients, mime_msg=msg, conn_id=conn_id, dryrun=dryrun)

[2024-04-04T09:56:53.190+0000] {configuration.py:1046} WARNING - section/key [smtp/smtp_user] not found in config
[2024-04-04T09:56:53.191+0000] {email.py:270} INFO - Email alerting: attempt 1
[2024-04-04T09:56:53.205+0000] {configuration.py:1046} WARNING - section/key [smtp/smtp_user] not found in config
[2024-04-04T09:56:53.207+0000] {email.py:270} INFO - Email alerting: attempt 1
[2024-04-04T09:56:53.210+0000] {taskinstance.py:837} ERROR - Failed to send email to: ['hieurio12@gmail.com']
Traceback (most recent call last):
  File "/home/airflow/.local/lib/python3.8/site-packages/airflow/models/taskinstance.py", line 2360, in _run_raw_task
    self._execute_task_with_callbacks(context, test_mode, session=session)
  File "/home/airflow/.local/lib/python3.8/site-packages/airflow/models/taskinstance.py", line 2532, in _execute_task_with_callbacks
    result = self._execute_task(context, task_orig)
  File "/home/airflow/.local/lib/python3.8/site-packages/airflow/models/taskinstance.py", line 2549, in _execute_task
    return _execute_task(self, context, task_orig)
  File "/home/airflow/.local/lib/python3.8/site-packages/airflow/models/taskinstance.py", line 444, in _execute_task
    result = _execute_callable(context=context, **execute_callable_kwargs)
  File "/home/airflow/.local/lib/python3.8/site-packages/airflow/models/taskinstance.py", line 414, in _execute_callable
    return execute_callable(context=context, **execute_callable_kwargs)
  File "/home/airflow/.local/lib/python3.8/site-packages/airflow/operators/bash.py", line 212, in execute
    raise AirflowException(
airflow.exceptions.AirflowException: Bash command failed. The command returned a non-zero exit code 1.

During handling of the above exception, another exception occurred:

Traceback (most recent call last):
  File "/home/airflow/.local/lib/python3.8/site-packages/airflow/models/taskinstance.py", line 1011, in _email_alert
    send_email(task.email, subject, html_content)
  File "/home/airflow/.local/lib/python3.8/site-packages/airflow/utils/email.py", line 80, in send_email
    return backend(
  File "/home/airflow/.local/lib/python3.8/site-packages/airflow/utils/email.py", line 154, in send_email_smtp
    send_mime_email(e_from=mail_from, e_to=recipients, mime_msg=msg, conn_id=conn_id, dryrun=dryrun)
  File "/home/airflow/.local/lib/python3.8/site-packages/airflow/utils/email.py", line 272, in send_mime_email
    smtp_conn = _get_smtp_connection(smtp_host, smtp_port, smtp_timeout, smtp_ssl)
  File "/home/airflow/.local/lib/python3.8/site-packages/airflow/utils/email.py", line 316, in _get_smtp_connection
    return smtplib.SMTP(host=host, port=port, timeout=timeout)
  File "/usr/local/lib/python3.8/smtplib.py", line 255, in __init__
    (code, msg) = self.connect(host, port)
  File "/usr/local/lib/python3.8/smtplib.py", line 339, in connect
    self.sock = self._get_socket(host, port, self.timeout)
  File "/usr/local/lib/python3.8/smtplib.py", line 310, in _get_socket
    return socket.create_connection((host, port), timeout,
  File "/usr/local/lib/python3.8/socket.py", line 808, in create_connection
    raise err
  File "/usr/local/lib/python3.8/socket.py", line 796, in create_connection
    sock.connect(sa)
OSError: [Errno 99] Cannot assign requested address

During handling of the above exception, another exception occurred:

Traceback (most recent call last):
  File "/home/airflow/.local/lib/python3.8/site-packages/airflow/models/taskinstance.py", line 835, in _handle_failure
    task_instance.email_alert(error, failure_context["task"])
  File "/home/airflow/.local/lib/python3.8/site-packages/airflow/models/taskinstance.py", line 2979, in email_alert
    _email_alert(task_instance=self, exception=exception, task=task)
  File "/home/airflow/.local/lib/python3.8/site-packages/airflow/models/taskinstance.py", line 1013, in _email_alert
    send_email(task.email, subject, html_content_err)
  File "/home/airflow/.local/lib/python3.8/site-packages/airflow/utils/email.py", line 80, in send_email
    return backend(
  File "/home/airflow/.local/lib/python3.8/site-packages/airflow/utils/email.py", line 154, in send_email_smtp
    send_mime_email(e_from=mail_from, e_to=recipients, mime_msg=msg, conn_id=conn_id, dryrun=dryrun)
  File "/home/airflow/.local/lib/python3.8/site-packages/airflow/utils/email.py", line 272, in send_mime_email
    smtp_conn = _get_smtp_connection(smtp_host, smtp_port, smtp_timeout, smtp_ssl)
  File "/home/airflow/.local/lib/python3.8/site-packages/airflow/utils/email.py", line 316, in _get_smtp_connection
    return smtplib.SMTP(host=host, port=port, timeout=timeout)
  File "/usr/local/lib/python3.8/smtplib.py", line 255, in __init__
    (code, msg) = self.connect(host, port)
  File "/usr/local/lib/python3.8/smtplib.py", line 339, in connect
    self.sock = self._get_socket(host, port, self.timeout)
  File "/usr/local/lib/python3.8/smtplib.py", line 310, in _get_socket
    return socket.create_connection((host, port), timeout,
  File "/usr/local/lib/python3.8/socket.py", line 808, in create_connection
    raise err
  File "/usr/local/lib/python3.8/socket.py", line 796, in create_connection
    sock.connect(sa)
OSError: [Errno 99] Cannot assign requested address
[2024-04-04T09:56:53.238+0000] {standard_task_runner.py:107} ERROR - Failed to execute job 5 for task crawl_job_task (Bash command failed. The command returned a non-zero exit code 1.; 328)
[2024-04-04T09:56:53.268+0000] {local_task_job_runner.py:234} INFO - Task exited with return code 1
[2024-04-04T09:56:53.302+0000] {taskinstance.py:3312} INFO - 0 downstream tasks scheduled from follow-on schedule check
